<?xml version="1.0" encoding="UTF-8"?>
<robot name="Robot">
    <link name="base">
        <inertial>
            <mass value="0"/>
            <inertia ixx="0" ixy="0" ixz="0" iyy="0" iyz="0" izz="0"/>
        </inertial>
    </link>
    <link name="right_end_effector_link">
        <inertial>
            <origin rpy="0.00000000 0.00000000 0.00000000" xyz="0.00000000 0.00000000 0.00000000"/>
            <mass value="0.00000000"/>
            <inertia ixx="0.00000000" ixy="0.00000000" ixz="0.00000000" iyy="0.00000000" iyz="0.00000000" izz="0.00000000"/>
        </inertial>
    </link>
    <link name="right_hand_pitch_link">
        <inertial>
            <origin rpy="0.00000000 0.00000000 0.00000000" xyz="0.00000000 -0.00129000 -0.01170000"/>
            <mass value="0.02950000"/>
            <inertia ixx="0.00000538" ixy="0.00000000" ixz="0.00000000" iyy="0.00001000" iyz="0.00000046" izz="0.00000892"/>
        </inertial>
    </link>
    <link name="right_hand_roll_link">
        <inertial>
            <origin rpy="0.00000000 0.00000000 0.00000000" xyz="0.00000000 -0.00129000 -0.01170000"/>
            <mass value="0.02950000"/>
            <inertia ixx="0.00000538" ixy="0.00000000" ixz="0.00000000" iyy="0.00001000" iyz="0.00000046" izz="0.00000892"/>
        </inertial>
    </link>
    <link name="right_hand_yaw_link">
        <inertial>
            <origin rpy="0.00000000 0.00000000 0.00000000" xyz="0.00003900 -0.00212000 -0.06117000"/>
            <mass value="0.89000000"/>
            <inertia ixx="0.00186600" ixy="0.00000030" ixz="-0.00001091" iyy="0.00186200" iyz="-0.00001679" izz="0.00032110"/>
        </inertial>
        <collision>
            <origin rpy="0.00000000 0.00000000 0.00000000" xyz="0.00108925  0.00064111 -0.07604285"/>
            <geometry>
                <cylinder radius="0.04157192" length="0.13918736"/>
            </geometry>
        </collision>
    </link>
    <link name="right_lower_arm_pitch_link">
        <inertial>
            <origin rpy="0.00000000 0.00000000 0.00000000" xyz="-0.00000169 -0.00785500 -0.02549000"/>
            <mass value="0.32000000"/>
            <inertia ixx="0.00029140" ixy="0.00000002" ixz="0.00000001" iyy="0.00028470" iyz="0.00004850" izz="0.00010900"/>
        </inertial>
    </link>
    <link name="right_upper_arm_pitch_link">
        <inertial>
            <origin rpy="0.00000000 0.00000000 0.00000000" xyz="0.00324000 -0.05330000  0.00018500"/>
            <mass value="0.81000000"/>
            <inertia ixx="0.00203000" ixy="0.00010400" ixz="0.00000030" iyy="0.00049900" iyz="-0.00000110" izz="0.00196000"/>
        </inertial>
    </link>
    <link name="right_upper_arm_roll_link">
        <inertial>
            <origin rpy="0.00000000 0.00000000 0.00000000" xyz="0.00342000 -0.01470000 -0.02320000"/>
            <mass value="0.50000000"/>
            <inertia ixx="0.00087500" ixy="0.00001598" ixz="0.00000296" iyy="0.00069600" iyz="-0.00028660" izz="0.00041210"/>
        </inertial>
    </link>
    <link name="right_upper_arm_yaw_link">
        <inertial>
            <origin rpy="0.00000000 0.00000000 0.00000000" xyz="0.00007600 -0.00203200 -0.08519000"/>
            <mass value="0.55000000"/>
            <inertia ixx="0.00354300" ixy="-0.00000019" ixz="-0.00000149" iyy="0.00353600" iyz="-0.00009890" izz="0.00025120"/>
        </inertial>
        <collision>
            <origin rpy="0.00000000 0.00000000 0.00000000" xyz="0.00003949  0.00089429 -0.07934004"/>
            <geometry>
                <cylinder radius="0.03623321" length="0.16988399"/>
            </geometry>
        </collision>
    </link>
    <link name="torso_link">
        <inertial>
            <origin rpy="0.00000000 0.00000000 0.00000000" xyz="-0.00667000  0.00015330  0.01837000"/>
            <mass value="6.40000000"/>
            <inertia ixx="0.04162000" ixy="0.00002011" ixz="-0.00169100" iyy="0.03127000" iyz="0.00001097" izz="0.02553000"/>
        </inertial>
        <collision>
            <origin rpy="0.00000000 0.00000000 0.00000000" xyz="-0.01581593  0.00519537 -0.01252051"/>
            <geometry>
                <cylinder radius="0.12742741" length="0.16038600"/>
            </geometry>
        </collision>
    </link>
    <link name="world_to_arm_offset">
        <inertial>
            <origin rpy="0.00000000 0.00000000 0.00000000" xyz="0.00000000 0.00000000 0.00000000"/>
            <mass value="1.00000000"/>
            <inertia ixx="1.00000000" ixy="0.00000000" ixz="0.00000000" iyy="1.00000000" iyz="0.00000000" izz="1.00000000"/>
        </inertial>
    </link>
    <joint name="fix_offset" type="fixed">
        <parent link="base"/>
        <child link="world_to_arm_offset"/>
        <origin rpy="0.00000000 0.00000000 0.00000000" xyz="-0.00414000  0.00000000  0.32901000"/>
        <axis xyz="100"/>
    </joint>
    <joint name="right_elbow_pitch_joint" type="revolute">
        <parent link="right_upper_arm_yaw_link"/>
        <child link="right_lower_arm_pitch_link"/>
        <origin rpy="0.00000000 0.00000000 0.00000000" xyz="0.00000000  0.00000000 -0.17510000"/>
        <axis xyz="0.00000000 1.00000000 0.00000000"/>
        <limit lower="-2.27000000" upper="2.27000000" effort="0" velocity="0"/>
    </joint>
    <joint name="right_end_effector_joint" type="fixed">
        <parent link="right_hand_pitch_link"/>
        <child link="right_end_effector_link"/>
        <origin rpy="0.00000000 0.00000000 0.00000000" xyz="0.00000000 0.00000000 0.00000000"/>
        <axis xyz="100"/>
    </joint>
    <joint name="right_shoulder_pitch_joint" type="revolute">
        <parent link="torso_link"/>
        <child link="right_upper_arm_pitch_link"/>
        <origin rpy="-0.43633000  0.00000000  0.00000000" xyz="0.00000000 -0.10111000  0.04714900"/>
        <axis xyz="0.00000000 1.00000000 0.00000000"/>
        <limit lower="-2.79000000" upper="1.92000000" effort="0" velocity="0"/>
    </joint>
    <joint name="right_shoulder_roll_joint" type="revolute">
        <parent link="right_upper_arm_pitch_link"/>
        <child link="right_upper_arm_roll_link"/>
        <origin rpy="0.43633000 0.00000000 0.00000000" xyz="0.00000000 -0.09515000  0.00000000"/>
        <axis xyz="1.00000000 0.00000000 0.00000000"/>
        <limit lower="-3.27000000" upper="0.57000000" effort="0" velocity="0"/>
    </joint>
    <joint name="right_shoulder_yaw_joint" type="revolute">
        <parent link="right_upper_arm_roll_link"/>
        <child link="right_upper_arm_yaw_link"/>
        <origin rpy="0.00000000 0.00000000 0.00000000" xyz="0.00000000 -0.04000000 -0.07095000"/>
        <axis xyz="0.00000000 0.00000000 1.00000000"/>
        <limit lower="-2.97000000" upper="2.97000000" effort="0" velocity="0"/>
    </joint>
    <joint name="right_wrist_pitch_joint" type="revolute">
        <parent link="right_hand_roll_link"/>
        <child link="right_hand_pitch_link"/>
        <origin rpy="0.00000000 0.00000000 0.00000000" xyz="0.00000000 0.00000000 0.00000000"/>
        <axis xyz="0.00000000 1.00000000 0.00000000"/>
        <limit lower="-0.61000000" upper="0.61000000" effort="0" velocity="0"/>
    </joint>
    <joint name="right_wrist_roll_joint" type="revolute">
        <parent link="right_hand_yaw_link"/>
        <child link="right_hand_roll_link"/>
        <origin rpy="0.00000000 0.00000000 0.00000000" xyz="0.00000000  0.00000000 -0.18765000"/>
        <axis xyz="1.00000000 0.00000000 0.00000000"/>
        <limit lower="-0.96000000" upper="0.87000000" effort="0" velocity="0"/>
    </joint>
    <joint name="right_wrist_yaw_joint" type="revolute">
        <parent link="right_lower_arm_pitch_link"/>
        <child link="right_hand_yaw_link"/>
        <origin rpy="0.00000000 0.00000000 0.00000000" xyz="0.00000000 -0.00005033 -0.05395000"/>
        <axis xyz="0.00000000 0.00000000 1.00000000"/>
        <limit lower="-2.97000000" upper="2.97000000" effort="0" velocity="0"/>
    </joint>
    <joint name="torso_joint" type="fixed">
        <parent link="world_to_arm_offset"/>
        <child link="torso_link"/>
        <origin rpy="0.00000000 0.00000000 0.00000000" xyz="-0.00414000  0.00000000  0.16071000"/>
        <axis xyz="100"/>
    </joint>
</robot>
