<?xml version="1.0" encoding="UTF-8"?>
<robot name="Robot">
    <link name="base">
        <inertial>
            <mass value="0"/>
            <inertia ixx="0" ixy="0" ixz="0" iyy="0" iyz="0" izz="0"/>
        </inertial>
    </link>
    <link name="right_arm_base_link">
        <inertial>
            <origin rpy="0.00000000 0.00000000 0.00000000" xyz="-0.00056307 -0.03893400 -0.00000319"/>
            <mass value="1.65800000"/>
            <inertia ixx="0.00105970" ixy="-0.00001982" ixz="0.00000017" iyy="0.00117870" iyz="-0.00000019" izz="0.00106470"/>
        </inertial>
    </link>
    <link name="right_arm_link1">
        <inertial>
            <origin rpy="0.00000000 0.00000000 0.00000000" xyz="0.00001500 -0.10525900  0.00195400"/>
            <mass value="1.16400000"/>
            <inertia ixx="0.00112500" ixy="0.00000000" ixz="0.00000000" iyy="0.00108400" iyz="-0.00002300" izz="0.00115800"/>
        </inertial>
    </link>
    <link name="right_arm_link2">
        <inertial>
            <origin rpy="0.00000000 0.00000000 0.00000000" xyz="-0.23622000 -0.01635400  0.00013183"/>
            <mass value="1.30000000"/>
            <inertia ixx="0.00060639" ixy="-0.00041823" ixz="-0.00014958" iyy="0.00759360" iyz="-0.00000809" izz="0.00757120"/>
        </inertial>
    </link>
    <link name="right_arm_link3">
        <inertial>
            <origin rpy="0.00000000 0.00000000 0.00000000" xyz="0.04511500 -0.05461600  0.00045613"/>
            <mass value="0.81800000"/>
            <inertia ixx="0.00060107" ixy="0.00022466" ixz="0.00000711" iyy="0.00139590" iyz="-0.00000975" izz="0.00150270"/>
        </inertial>
    </link>
    <link name="right_arm_link4">
        <inertial>
            <origin rpy="0.00000000 0.00000000 0.00000000" xyz="0.24285000 -0.00237630 -0.00000035"/>
            <mass value="0.69400000"/>
            <inertia ixx="0.00008450" ixy="0.00000083" ixz="0.00000000" iyy="0.00010174" iyz="0.00000001" izz="0.00009704"/>
        </inertial>
    </link>
    <link name="right_arm_link5">
        <inertial>
            <origin rpy="0.00000000 0.00000000 0.00000000" xyz="0.05430900 -0.00418070 -0.00000386"/>
            <mass value="0.41700000"/>
            <inertia ixx="0.00008400" ixy="-0.00001623" ixz="-0.00000007" iyy="0.00009850" iyz="-0.00000001" izz="0.00011333"/>
        </inertial>
    </link>
    <link name="right_arm_link6">
        <inertial>
            <origin rpy="0.00000000 0.00000000 0.00000000" xyz="0.02813800 0.00000012 0.00000005"/>
            <mass value="0.03700000"/>
            <inertia ixx="0.00000357" ixy="0.00000000" ixz="0.00000000" iyy="0.00000202" iyz="-0.00000000" izz="0.00000202"/>
        </inertial>
    </link>
    <link name="right_gripper_link">
        <inertial>
            <origin rpy="0.00000000 0.00000000 0.00000000" xyz="-0.03110724 -0.00000014 -0.00000014"/>
            <mass value="0.60400000"/>
            <inertia ixx="0.00017588" ixy="0.00000000" ixz="-0.00000000" iyy="0.00009864" iyz="-0.00000008" izz="0.00016512"/>
        </inertial>
    </link>
    <link name="world_to_arm_offset">
        <inertial>
            <origin rpy="0.00000000 0.00000000 0.00000000" xyz="0.00000000 0.00000000 0.00000000"/>
            <mass value="1.00000000"/>
            <inertia ixx="1.00000000" ixy="0.00000000" ixz="0.00000000" iyy="1.00000000" iyz="0.00000000" izz="1.00000000"/>
        </inertial>
    </link>
    <joint name="fix_offset" type="fixed">
        <parent link="base"/>
        <child link="world_to_arm_offset"/>
        <origin rpy="0.00000000 0.00000000 0.00000000" xyz="-0.03206722 -0.09723500  1.40347000"/>
        <axis xyz="100"/>
    </joint>
    <joint name="right_arm_base_joint" type="fixed">
        <parent link="world_to_arm_offset"/>
        <child link="right_arm_base_link"/>
        <origin rpy="0.00000000 0.00000000 0.00000000" xyz="0.00077778 -0.09723500  0.30285000"/>
        <axis xyz="100"/>
    </joint>
    <joint name="right_arm_joint1" type="revolute">
        <parent link="right_arm_base_link"/>
        <child link="right_arm_link1"/>
        <origin rpy="0.00000000 0.00000000 0.00000000" xyz="-0.00111450 -0.04460000  0.00000000"/>
        <axis xyz="0.00000000 -1.00000000  0.00000000"/>
        <limit lower="-2.87980000" upper="2.87980000" effort="0" velocity="0"/>
    </joint>
    <joint name="right_arm_joint2" type="revolute">
        <parent link="right_arm_link1"/>
        <child link="right_arm_link2"/>
        <origin rpy="0.00000000 0.00000000 0.00000000" xyz="0.00000000 -0.10610000  0.00000000"/>
        <axis xyz="0.00000000 0.00000000 1.00000000"/>
        <limit lower="0.00000000" upper="3.22890000" effort="0" velocity="0"/>
    </joint>
    <joint name="right_arm_joint3" type="revolute">
        <parent link="right_arm_link2"/>
        <child link="right_arm_link3"/>
        <origin rpy="0.00000000 0.00000000 0.00000000" xyz="-0.34928000 -0.02000200  0.00000000"/>
        <axis xyz="0.00000000 0.00000000 1.00000000"/>
        <limit lower="-3.31610000" upper="0.00000000" effort="0" velocity="0"/>
    </joint>
    <joint name="right_arm_joint4" type="revolute">
        <parent link="right_arm_link3"/>
        <child link="right_arm_link4"/>
        <origin rpy="0.00000000 0.00000000 0.00000000" xyz="0.02735000 -0.06976700  0.00000000"/>
        <axis xyz="1.00000000 0.00000000 0.00000000"/>
        <limit lower="-2.87980000" upper="2.87980000" effort="0" velocity="0"/>
    </joint>
    <joint name="right_arm_joint5" type="revolute">
        <parent link="right_arm_link4"/>
        <child link="right_arm_link5"/>
        <origin rpy="0.00000000 0.00000000 0.00000000" xyz="0.24630000 0.00050106 0.00000000"/>
        <axis xyz="0.00000000 -1.00000000  0.00000000"/>
        <limit lower="-1.65810000" upper="1.65810000" effort="0" velocity="0"/>
    </joint>
    <joint name="right_arm_joint6" type="revolute">
        <parent link="right_arm_link5"/>
        <child link="right_arm_link6"/>
        <origin rpy="0.00000000 0.00000000 0.00000000" xyz="0.05824900 -0.00049975  0.00000000"/>
        <axis xyz="1.00000000 0.00000000 0.00000000"/>
        <limit lower="-2.87980000" upper="2.87980000" effort="0" velocity="0"/>
    </joint>
    <joint name="right_gripper_joint" type="fixed">
        <parent link="right_arm_link6"/>
        <child link="right_gripper_link"/>
        <origin rpy="0.00000000 0.00000000 0.00000000" xyz="0.10390000 0.00000000 0.00000000"/>
        <axis xyz="100"/>
    </joint>
</robot>
