<?xml version='1.0' encoding='utf-8'?>
<robot name="right_arm_aligned"><link name="right_arm_link2">
    <inertial>
      <origin xyz="-0.23622 -0.016354 0.00013183" rpy="0 0 0" />
      <mass value="1.3" />
      <inertia ixx="0.00060639" ixy="-0.00041823" ixz="-0.00014958" iyy="0.0075936" iyz="-8.0947E-06" izz="0.0075712" />
    </inertial>
    <visual>
      <origin xyz="0 0 0" rpy="0 0 0" />
      <geometry>
        <mesh filename="package://r1_v2_1_0/meshes/right_arm_link2.STL" />
      </geometry>
      <material name="">
        <color rgba="0.79216 0.81961 0.93333 1" />
      </material>
    </visual>
    <collision>
      <origin xyz="0 0 0" rpy="0 0 0" />
      <geometry>
        <mesh filename="package://r1_v2_1_0/meshes/right_arm_link2.STL" />
      </geometry>
    </collision>
  </link>
  <link name="right_arm_link3">
    <inertial>
      <origin xyz="0.045115 -0.054616 0.00045613" rpy="0 0 0" />
      <mass value="0.818" />
      <inertia ixx="0.00060107" ixy="0.00022466" ixz="7.1148E-06" iyy="0.0013959" iyz="-9.7492E-06" izz="0.0015027" />
    </inertial>
    <visual>
      <origin xyz="0 0 0" rpy="0 0 0" />
      <geometry>
        <mesh filename="package://r1_v2_1_0/meshes/right_arm_link3.STL" />
      </geometry>
      <material name="">
        <color rgba="0.79216 0.81961 0.93333 1" />
      </material>
    </visual>
    <collision>
      <origin xyz="0 0 0" rpy="0 0 0" />
      <geometry>
        <mesh filename="package://r1_v2_1_0/meshes/right_arm_link3.STL" />
      </geometry>
    </collision>
  </link>
  <link name="right_arm_base_link">
    <inertial>
      <origin xyz="-0.00056307 -0.038934 -3.1915E-06" rpy="0 0 0" />
      <mass value="1.658" />
      <inertia ixx="0.0010597" ixy="-1.9822E-05" ixz="1.6753E-07" iyy="0.0011787" iyz="-1.915E-07" izz="0.0010647" />
    </inertial>
    <visual>
      <origin xyz="0 0 0" rpy="0 0 0" />
      <geometry>
        <mesh filename="package://r1_v2_1_0/meshes/right_arm_base_link.STL" />
      </geometry>
      <material name="">
        <color rgba="0.79216 0.81961 0.93333 1" />
      </material>
    </visual>
    <collision>
      <origin xyz="0 0 0" rpy="0 0 0" />
      <geometry>
        <mesh filename="package://r1_v2_1_0/meshes/right_arm_base_link.STL" />
      </geometry>
    </collision>
  </link>
  <link name="right_arm_link6">
    <inertial>
      <origin xyz="0.028138 1.2134E-07 5.405E-08" rpy="0 0 0" />
      <mass value="0.037" />
      <inertia ixx="3.5662E-06" ixy="6.6514E-12" ixz="2.9628E-12" iyy="2.0238E-06" iyz="-4.0687E-12" izz="2.0238E-06" />
    </inertial>
    <visual>
      <origin xyz="0 0 0" rpy="0 0 0" />
      <geometry>
        <mesh filename="package://r1_v2_1_0/meshes/right_arm_link6.STL" />
      </geometry>
      <material name="">
        <color rgba="0.82353 0.82353 1 1" />
      </material>
    </visual>
    <collision>
      <origin xyz="0 0 0" rpy="0 0 0" />
      <geometry>
        <mesh filename="package://r1_v2_1_0/meshes/right_arm_link6.STL" />
      </geometry>
    </collision>
  </link>
  <link name="right_arm_link4">
    <inertial>
      <origin xyz="0.24285 -0.0023763 -3.4603E-07" rpy="0 0 0" />
      <mass value="0.694" />
      <inertia ixx="8.45E-05" ixy="8.2612E-07" ixz="2.2124E-09" iyy="0.00010174" iyz="5.3644E-09" izz="9.7044E-05" />
    </inertial>
    <visual>
      <origin xyz="0 0 0" rpy="0 0 0" />
      <geometry>
        <mesh filename="package://r1_v2_1_0/meshes/right_arm_link4.STL" />
      </geometry>
      <material name="">
        <color rgba="1 1 1 1" />
      </material>
    </visual>
    <collision>
      <origin xyz="0 0 0" rpy="0 0 0" />
      <geometry>
        <mesh filename="package://r1_v2_1_0/meshes/right_arm_link4.STL" />
      </geometry>
    </collision>
  </link>
  <link name="right_arm_link5">
    <inertial>
      <origin xyz="0.054309 -0.0041807 -3.8613E-06" rpy="0 0 0" />
      <mass value="0.417" />
      <inertia ixx="8.4E-05" ixy="-1.6234E-05" ixz="-7.4239E-08" iyy="9.8498E-05" iyz="-1.3874E-08" izz="0.00011333" />
    </inertial>
    <visual>
      <origin xyz="0 0 0" rpy="0 0 0" />
      <geometry>
        <mesh filename="package://r1_v2_1_0/meshes/right_arm_link5.STL" />
      </geometry>
      <material name="">
        <color rgba="1 1 1 1" />
      </material>
    </visual>
    <collision>
      <origin xyz="0 0 0" rpy="0 0 0" />
      <geometry>
        <mesh filename="package://r1_v2_1_0/meshes/right_arm_link5.STL" />
      </geometry>
    </collision>
  </link>
  <link name="torso_link4">
    <inertial>
      <origin xyz="-3.7511E-08 5.2756E-07 0.018688" rpy="0 0 0" />
      <mass value="7.4" />
      <inertia ixx="0.0014989" ixy="2.9183E-08" ixz="-7.7884E-10" iyy="0.001499" iyz="-1.2513E-10" izz="0.0019043" />
    </inertial>
    <visual>
      <origin xyz="0 0 0" rpy="0 0 0" />
      <geometry>
        <mesh filename="package://r1_v2_1_0/meshes/torso_link4.STL" />
      </geometry>
      <material name="">
        <color rgba="0.82353 0.82353 1 1" />
      </material>
    </visual>
    <collision>
      <origin xyz="0 0 0" rpy="0 0 0" />
      <geometry>
        <mesh filename="package://r1_v2_1_0/meshes/torso_link4.STL" />
      </geometry>
    </collision>
  </link>
  <link name="right_arm_link1">
    <inertial>
      <origin xyz="0.000015 -0.105259 0.001954" rpy="0 0 0" />
      <mass value="1.164" />
      <inertia ixx="0.001125" ixy="0.0" ixz="0.0" iyy="0.001084" iyz="-0.000023" izz="0.001158" />
    </inertial>
    <visual>
      <origin xyz="0 0 0" rpy="0 0 0" />
      <geometry>
        <mesh filename="package://r1_v2_1_0/meshes/right_arm_link1.STL" />
      </geometry>
      <material name="">
        <color rgba="0.79216 0.81961 0.93333 1" />
      </material>
    </visual>
    <collision>
      <origin xyz="0 0 0" rpy="0 0 0" />
      <geometry>
        <mesh filename="package://r1_v2_1_0/meshes/right_arm_link1.STL" />
      </geometry>
    </collision>
  </link>
  <link name="right_arm_root"><inertial><origin xyz="0 0 0" rpy="0 0 0" /><mass value="0.001" /><inertia ixx="1e-6" ixy="0" ixz="0" iyy="1e-6" iyz="0" izz="1e-6" /></inertial></link><joint name="right_arm_joint1" type="revolute">
    <origin xyz="-0.0011145 -0.0446 0" rpy="0 0 0" />
    <parent link="right_arm_base_link" />
    <child link="right_arm_link1" />
    <axis xyz="0 -1 0" />
    <limit lower="-2.8798" upper="2.8798" effort="40" velocity="20.944" />
  </joint>
  <joint name="right_arm_joint2" type="revolute">
    <origin xyz="0 -0.1061 0" rpy="0 0 0" />
    <parent link="right_arm_link1" />
    <child link="right_arm_link2" />
    <axis xyz="0 0 1" />
    <limit lower="0" upper="3.2289" effort="40" velocity="20.944" />
  </joint>
  <joint name="right_arm_base_joint" type="fixed">
    <origin xyz="-0.03206722 -0.097235 1.4034700000000002" rpy="-0.0 0.0 0.0" />
    <parent link="right_arm_root" />
    <child link="right_arm_base_link" />
    <axis xyz="0 0 0" />
  </joint>
  <joint name="right_arm_joint3" type="revolute">
    <origin xyz="-0.34928 -0.020002 0" rpy="0 0 0" />
    <parent link="right_arm_link2" />
    <child link="right_arm_link3" />
    <axis xyz="0 0 1" />
    <limit lower="-3.3161" upper="0" effort="27" velocity="7.5398" />
  </joint>
  <joint name="right_arm_joint6" type="revolute">
    <origin xyz="0.058249 -0.00049975 0" rpy="0 0 0" />
    <parent link="right_arm_link5" />
    <child link="right_arm_link6" />
    <axis xyz="1 0 0" />
    <limit lower="-2.8798" upper="2.8798" effort="7" velocity="25.133" />
  </joint>
  <joint name="right_arm_joint5" type="revolute">
    <origin xyz="0.2463 0.00050106 0" rpy="0 0 0" />
    <parent link="right_arm_link4" />
    <child link="right_arm_link5" />
    <axis xyz="0 -1 0" />
    <limit lower="-1.6581" upper="1.6581" effort="7" velocity="25.133" />
  </joint>
  <joint name="right_arm_joint4" type="revolute">
    <origin xyz="0.02735 -0.069767 0" rpy="0 0 0" />
    <parent link="right_arm_link3" />
    <child link="right_arm_link4" />
    <axis xyz="1 0 0" />
    <limit lower="-2.8798" upper="2.8798" effort="7" velocity="25.133" />
  </joint>
  </robot>