<?xml version="1.0" encoding="utf-8"?>
<!-- This URDF was automatically created by SolidWorks to URDF Exporter! Originally created by Stephen Brawner (brawner@gmail.com) 
     Commit Version: 1.5.1-0-g916b5db  Build Version: 1.5.7152.31018
     For more information, please see http://wiki.ros.org/sw_urdf_exporter -->
<robot
  name="Marvin M6-S-R-CCS-689 urdf">
  <link
    name="Base_R">
    <inertial>
      <origin
        xyz="0.0001427 1.626E-05 0.039067"
        rpy="0 0 0" />
      <mass
        value="1.2946" />
      <inertia
        ixx="0.0031404"
        ixy="1.07E-06"
        ixz="-9.1E-07"
        iyy="0.0031251"
        iyz="3.9E-06"
        izz="0.0014169" />
    </inertial>
    <visual>
      <origin
        xyz="0 0 0"
        rpy="0 0 0" />
      <geometry>
        <mesh
          filename="package://Marvin M6-S-R-CCS-689_URDF/meshes/Base_R.STL" />
      </geometry>
      <material
        name="">
        <color
          rgba="1 0 0 1" />
      </material>
    </visual>
    <collision>
      <origin
        xyz="0 0 0"
        rpy="0 0 0" />
      <geometry>
        <mesh
          filename="package://Marvin M6-S-R-CCS-689_URDF/meshes/Base_R.STL" />
      </geometry>
    </collision>
  </link>
  <link
    name="Link1_R">
    <inertial>
      <origin
        xyz="1.875E-05 0.006003 0.1438"
        rpy="0 0 0" />
      <mass
        value="2.0926" />
      <inertia
        ixx="0.0485"
        ixy="2.85E-06"
        ixz="9.42E-06"
        iyy="0.048824"
        iyz="0.0021904"
        izz="0.0020558" />
    </inertial>
    <visual>
      <origin
        xyz="0 0 0"
        rpy="0 0 0" />
      <geometry>
        <mesh
          filename="package://Marvin M6-S-R-CCS-689_URDF/meshes/Link1_R.STL" />
      </geometry>
      <material
        name="">
        <color
          rgba="0 1 0 1" />
      </material>
    </visual>
    <collision>
      <origin
        xyz="0 0 0"
        rpy="0 0 0" />
      <geometry>
        <mesh
          filename="package://Marvin M6-S-R-CCS-689_URDF/meshes/Link1_R.STL" />
      </geometry>
    </collision>
  </link>
  <joint
    name="Joint1_R"
    type="revolute">
    <origin
      xyz="0 0 0"
      rpy="0 0 0" />
    <parent
      link="Base_R" />
    <child
      link="Link1_R" />
    <axis
      xyz="0 0 1" />
    <limit
      lower="-3.1067"
      upper="3.1067"
      effort="108"
      velocity="3.1416" />
  </joint>
  <link
    name="Link2_R">
    <inertial>
      <origin
        xyz="-7.03E-06 0.05542 0.010995"
        rpy="0 0 0" />
      <mass
        value="1.9432" />
      <inertia
        ixx="0.016558"
        ixy="-6.34E-06"
        ixz="1.91E-06"
        iyy="0.0033963"
        iyz="-6.31E-06"
        izz="0.015504" />
    </inertial>
    <visual>
      <origin
        xyz="0 0 0"
        rpy="0 0 0" />
      <geometry>
        <mesh
          filename="package://Marvin M6-S-R-CCS-689_URDF/meshes/Link2_R.STL" />
      </geometry>
      <material
        name="">
        <color
          rgba="0 0 1 1" />
      </material>
    </visual>
    <collision>
      <origin
        xyz="0 0 0"
        rpy="0 0 0" />
      <geometry>
        <mesh
          filename="package://Marvin M6-S-R-CCS-689_URDF/meshes/Link2_R.STL" />
      </geometry>
    </collision>
  </link>
  <joint
    name="Joint2_R"
    type="revolute">
    <origin
      xyz="0 0 0.1745"
      rpy="1.5708 0 0" />
    <parent
      link="Link1_R" />
    <child
      link="Link2_R" />
    <axis
      xyz="0 0 1" />
    <limit
      lower="-2.0944"
      upper="2.0944"
      effort="108"
      velocity="3.1416" />
  </joint>
  <link
    name="Link3_R">
    <inertial>
      <origin
        xyz="0.0087411 0.0019043 0.23487"
        rpy="0 0 0" />
      <mass
        value="1.6913" />
      <inertia
        ixx="0.099807"
        ixy="6.153E-05"
        ixz="0.0042654"
        iyy="0.10032"
        iyz="0.0009332"
        izz="0.0017797" />
    </inertial>
    <visual>
      <origin
        xyz="0 0 0"
        rpy="0 0 0" />
      <geometry>
        <mesh
          filename="package://Marvin M6-S-R-CCS-689_URDF/meshes/Link3_R.STL" />
      </geometry>
      <material
        name="">
        <color
          rgba="1 0 0 1" />
      </material>
    </visual>
    <collision>
      <origin
        xyz="0 0 0"
        rpy="0 0 0" />
      <geometry>
        <mesh
          filename="package://Marvin M6-S-R-CCS-689_URDF/meshes/Link3_R.STL" />
      </geometry>
    </collision>
  </link>
  <joint
    name="Joint3_R"
    type="revolute">
    <origin
      xyz="0 0 0"
      rpy="-1.5708 0 0" />
    <parent
      link="Link2_R" />
    <child
      link="Link3_R" />
    <axis
      xyz="0 0 1" />
    <limit
      lower="-3.1067"
      upper="3.1067"
      effort="66"
      velocity="3.1416" />
  </joint>
  <link
    name="Link4_R">
    <inertial>
      <origin
        xyz="-0.0086935 0.045984 0.011135"
        rpy="0 0 0" />
      <mass
        value="1.5332" />
      <inertia
        ixx="0.0087075"
        ixy="-0.0012304"
        ixz="-1.947E-05"
        iyy="0.0023918"
        iyz="9.793E-05"
        izz="0.0082548" />
    </inertial>
    <visual>
      <origin
        xyz="0 0 0"
        rpy="0 0 0" />
      <geometry>
        <mesh
          filename="package://Marvin M6-S-R-CCS-689_URDF/meshes/Link4_R.STL" />
      </geometry>
      <material
        name="">
        <color
          rgba="0 1 0 1" />
      </material>
    </visual>
    <collision>
      <origin
        xyz="0 0 0"
        rpy="0 0 0" />
      <geometry>
        <mesh
          filename="package://Marvin M6-S-R-CCS-689_URDF/meshes/Link4_R.STL" />
      </geometry>
    </collision>
  </link>
  <joint
    name="Joint4_R"
    type="revolute">
    <origin
      xyz="0.018 0 0.287"
      rpy="1.5708 0 0" />
    <parent
      link="Link3_R" />
    <child
      link="Link4_R" />
    <axis
      xyz="0 0 1" />
    <limit
      lower="-2.5307"
      upper="1.0472"
      effort="66"
      velocity="3.1416" />
  </joint>
  <link
    name="Link5_R">
    <inertial>
      <origin
        xyz=" 0.00036663 -0.00041429 0.19889130 "
        rpy="0 0 0" />
      <mass
        value="1.9854" />
      <inertia
        ixx=" 0.08421414 "
        ixy=" -0.00003503 "
        ixz=" 0.00019071 "
        iyy=" 0.08380223"
        iyz=" -0.00019334 "
        izz=" 0.00209565" />
    </inertial>
    <visual>
      <origin
        xyz="0 0 0"
        rpy="0 0 0" />
      <geometry>
        <mesh
          filename="package://Marvin M6-S-R-CCS-689_URDF/meshes/Link5_R.STL" />
      </geometry>
      <material
        name="">
        <color
          rgba="0 0 1 1" />
      </material>
    </visual>
    <collision>
      <origin
        xyz="0 0 0"
        rpy="0 0 0" />
      <geometry>
        <mesh
          filename="package://Marvin M6-S-R-CCS-689_URDF/meshes/Link5_R.STL" />
      </geometry>
    </collision>
  </link>
  <joint
    name="Joint5_R"
    type="revolute">
    <origin
      xyz="-0.018 0 0"
      rpy="-1.5708 0 0" />
    <parent
      link="Link4_R" />
    <child
      link="Link5_R" />
    <axis
      xyz="0 0 1" />
    <limit
      lower="-3.1067"
      upper="3.1067"
      effort="18"
      velocity="3.1416" />
  </joint>
  <link
    name="Link6_R">
    <inertial>
      <origin
        xyz=" -0.00458177 -0.00027029 0.00009098"
        rpy="0 0 0" />
      <mass
        value=" 0.64594816" />
      <inertia
        ixx=" 0.00047715"
        ixy=" 0.00000219"
        ixz=" -0.00000223"
        iyy=" 0.00040547"
        iyz=" 0.00000069"
        izz=" 0.00037475" />
    </inertial>
    <visual>
      <origin
        xyz="0 0 0"
        rpy="0 0 0" />
      <geometry>
        <mesh
          filename="package://Marvin M6-S-R-CCS-689_URDF/meshes/Link6_R.STL" />
      </geometry>
      <material
        name="">
        <color
          rgba="1 0 0 1" />
      </material>
    </visual>
    <collision>
      <origin
        xyz="0 0 0"
        rpy="0 0 0" />
      <geometry>
        <mesh
          filename="package://Marvin M6-S-R-CCS-689_URDF/meshes/Link6_R.STL" />
      </geometry>
    </collision>
  </link>
  <joint
    name="Joint6_R"
    type="revolute">
    <origin
      xyz="0 0 0.314"
      rpy="1.5708 0 0" />
    <parent
      link="Link5_R" />
    <child
      link="Link6_R" />
    <axis
      xyz="0 0 1" />
    <limit
      lower="-1.0472"
      upper="1.0472"
      effort="18"
      velocity="3.1416" />
  </joint>
  <link
    name="Link7_R">
    <inertial>
      <origin
        xyz=" 0.04498772 0.00004226 -0.00555813"
        rpy="0 0 0" />
      <mass
        value="0.31658" />
      <inertia
        ixx="0.00038289"
        ixy="7.4E-07"
        ixz="1.403E-05"
        iyy="0.00133"
        iyz="-6.1E-07"
        izz="0.0011774" />
    </inertial>
    <visual>
      <origin
        xyz="0 0 0"
        rpy="0 0 0" />
      <geometry>
        <mesh
          filename="package://Marvin M6-S-R-CCS-689_URDF/meshes/Link7_R.STL" />
      </geometry>
      <material
        name="">
        <color
          rgba="0 1 0 1" />
      </material>
    </visual>
    <collision>
      <origin
        xyz="0 0 0"
        rpy="0 0 0" />
      <geometry>
        <mesh
          filename="package://Marvin M6-S-R-CCS-689_URDF/meshes/Link7_R.STL" />
      </geometry>
    </collision>
  </link>
  <joint
    name="Joint7_R"
    type="revolute">
    <origin
      xyz="0 0 0"
      rpy="1.5708 0 1.5708" />
    <parent
      link="Link6_R" />
    <child
      link="Link7_R" />
    <axis
      xyz="0 0 1" />
    <limit
      lower="-1.5708"
      upper="1.5708"
      effort="18"
      velocity="3.1416" />
  </joint>
</robot>
